<?xml version="1.0" encoding="UTF-8"?>
<!-- Generated by org.testng.reporters.JUnitReportReporter -->
<testsuite skipped="1" hostname="Isakov-MBP.local" name="com.java4qa.addressbook.tests.ContactAddToGroupTests" tests="3" failures="0" timestamp="25 Jan 2018 11:05:30 GMT" time="0.663" errors="2">
  <testcase name="testContactAddToGroup" time="0.001" classname="com.java4qa.addressbook.tests.ContactAddToGroupTests">
    <skipped/>
  </testcase> <!-- testContactAddToGroup -->
  <testcase name="tearDown" time="0.001" classname="com.java4qa.addressbook.tests.ContactAddToGroupTests">
    <error type="java.lang.NullPointerException">
      <![CDATA[java.lang.NullPointerExceptionat com.java4qa.addressbook.appmanager.ApplicationManager.stop(ApplicationManager.java:59)at com.java4qa.addressbook.tests.TestBase.tearDown(TestBase.java:42)at sun.reflect.NativeMethodAccessorImpl.invoke0(Native Method)at sun.reflect.NativeMethodAccessorImpl.invoke(NativeMethodAccessorImpl.java:62)at sun.reflect.DelegatingMethodAccessorImpl.invoke(DelegatingMethodAccessorImpl.java:43)at java.lang.reflect.Method.invoke(Method.java:498)at org.testng.internal.MethodInvocationHelper.invokeMethod(MethodInvocationHelper.java:124)at org.testng.internal.MethodInvocationHelper.invokeMethodConsideringTimeout(MethodInvocationHelper.java:59)at org.testng.internal.Invoker.invokeConfigurationMethod(Invoker.java:451)at org.testng.internal.Invoker.invokeConfigurations(Invoker.java:222)at org.testng.internal.Invoker.invokeConfigurations(Invoker.java:142)at org.testng.SuiteRunner.privateRun(SuiteRunner.java:425)at org.testng.SuiteRunner.run(SuiteRunner.java:364)at org.testng.SuiteRunnerWorker.runSuite(SuiteRunnerWorker.java:52)at org.testng.SuiteRunnerWorker.run(SuiteRunnerWorker.java:84)at org.testng.TestNG.runSuitesSequentially(TestNG.java:1187)at org.testng.TestNG.runSuitesLocally(TestNG.java:1116)at org.testng.TestNG.runSuites(TestNG.java:1028)at org.testng.TestNG.run(TestNG.java:996)at org.testng.IDEARemoteTestNG.run(IDEARemoteTestNG.java:72)at org.testng.RemoteTestNGStarter.main(RemoteTestNGStarter.java:123)]]>
    </error>
  </testcase> <!-- tearDown -->
  <testcase name="setUp" time="0.661" classname="com.java4qa.addressbook.tests.ContactAddToGroupTests">
    <error type="org.hibernate.service.spi.ServiceException" message="Unable to create requested service [org.hibernate.engine.jdbc.env.spi.JdbcEnvironment]">
      <![CDATA[org.hibernate.service.spi.ServiceException: Unable to create requested service [org.hibernate.engine.jdbc.env.spi.JdbcEnvironment]at org.hibernate.service.internal.AbstractServiceRegistryImpl.createService(AbstractServiceRegistryImpl.java:271)at org.hibernate.service.internal.AbstractServiceRegistryImpl.initializeService(AbstractServiceRegistryImpl.java:233)at org.hibernate.service.internal.AbstractServiceRegistryImpl.getService(AbstractServiceRegistryImpl.java:210)at org.hibernate.engine.jdbc.internal.JdbcServicesImpl.configure(JdbcServicesImpl.java:51)at org.hibernate.boot.registry.internal.StandardServiceRegistryImpl.configureService(StandardServiceRegistryImpl.java:94)at org.hibernate.service.internal.AbstractServiceRegistryImpl.initializeService(AbstractServiceRegistryImpl.java:242)at org.hibernate.service.internal.AbstractServiceRegistryImpl.getService(AbstractServiceRegistryImpl.java:210)at org.hibernate.boot.model.process.spi.MetadataBuildingProcess.handleTypes(MetadataBuildingProcess.java:352)at org.hibernate.boot.model.process.spi.MetadataBuildingProcess.complete(MetadataBuildingProcess.java:111)at org.hibernate.boot.model.process.spi.MetadataBuildingProcess.build(MetadataBuildingProcess.java:83)at org.hibernate.boot.internal.MetadataBuilderImpl.build(MetadataBuilderImpl.java:418)at org.hibernate.boot.internal.MetadataBuilderImpl.build(MetadataBuilderImpl.java:87)at org.hibernate.boot.MetadataSources.buildMetadata(MetadataSources.java:179)at com.java4qa.addressbook.appmanager.DbHelper.<init>(DbHelper.java:28)at com.java4qa.addressbook.appmanager.ApplicationManager.init(ApplicationManager.java:36)at com.java4qa.addressbook.tests.TestBase.setUp(TestBase.java:37)at sun.reflect.NativeMethodAccessorImpl.invoke0(Native Method)at sun.reflect.NativeMethodAccessorImpl.invoke(NativeMethodAccessorImpl.java:62)at sun.reflect.DelegatingMethodAccessorImpl.invoke(DelegatingMethodAccessorImpl.java:43)at java.lang.reflect.Method.invoke(Method.java:498)at org.testng.internal.MethodInvocationHelper.invokeMethod(MethodInvocationHelper.java:124)at org.testng.internal.MethodInvocationHelper.invokeMethodConsideringTimeout(MethodInvocationHelper.java:59)at org.testng.internal.Invoker.invokeConfigurationMethod(Invoker.java:451)at org.testng.internal.Invoker.invokeConfigurations(Invoker.java:222)at org.testng.internal.Invoker.invokeConfigurations(Invoker.java:142)at org.testng.SuiteRunner.privateRun(SuiteRunner.java:401)at org.testng.SuiteRunner.run(SuiteRunner.java:364)at org.testng.SuiteRunnerWorker.runSuite(SuiteRunnerWorker.java:52)at org.testng.SuiteRunnerWorker.run(SuiteRunnerWorker.java:84)at org.testng.TestNG.runSuitesSequentially(TestNG.java:1187)at org.testng.TestNG.runSuitesLocally(TestNG.java:1116)at org.testng.TestNG.runSuites(TestNG.java:1028)at org.testng.TestNG.run(TestNG.java:996)at org.testng.IDEARemoteTestNG.run(IDEARemoteTestNG.java:72)at org.testng.RemoteTestNGStarter.main(RemoteTestNGStarter.java:123)Caused by: org.hibernate.exception.JDBCConnectionException: Error calling Driver#connectat org.hibernate.exception.internal.SQLStateConversionDelegate.convert(SQLStateConversionDelegate.java:115)at org.hibernate.engine.jdbc.connections.internal.BasicConnectionCreator$1$1.convert(BasicConnectionCreator.java:101)at org.hibernate.engine.jdbc.connections.internal.BasicConnectionCreator.convertSqlException(BasicConnectionCreator.java:123)at org.hibernate.engine.jdbc.connections.internal.DriverConnectionCreator.makeConnection(DriverConnectionCreator.java:41)at org.hibernate.engine.jdbc.connections.internal.BasicConnectionCreator.createConnection(BasicConnectionCreator.java:58)at org.hibernate.engine.jdbc.connections.internal.PooledConnections.addConnections(PooledConnections.java:123)at org.hibernate.engine.jdbc.connections.internal.PooledConnections.<init>(PooledConnections.java:42)at org.hibernate.engine.jdbc.connections.internal.PooledConnections.<init>(PooledConnections.java:20)at org.hibernate.engine.jdbc.connections.internal.PooledConnections$Builder.build(PooledConnections.java:161)at org.hibernate.engine.jdbc.connections.internal.DriverManagerConnectionProviderImpl.buildPool(DriverManagerConnectionProviderImpl.java:109)at org.hibernate.engine.jdbc.connections.internal.DriverManagerConnectionProviderImpl.configure(DriverManagerConnectionProviderImpl.java:72)at org.hibernate.boot.registry.internal.StandardServiceRegistryImpl.configureService(StandardServiceRegistryImpl.java:94)at org.hibernate.service.internal.AbstractServiceRegistryImpl.initializeService(AbstractServiceRegistryImpl.java:242)at org.hibernate.service.internal.AbstractServiceRegistryImpl.getService(AbstractServiceRegistryImpl.java:210)at org.hibernate.engine.jdbc.env.internal.JdbcEnvironmentInitiator.buildJdbcConnectionAccess(JdbcEnvironmentInitiator.java:145)at org.hibernate.engine.jdbc.env.internal.JdbcEnvironmentInitiator.initiateService(JdbcEnvironmentInitiator.java:66)at org.hibernate.engine.jdbc.env.internal.JdbcEnvironmentInitiator.initiateService(JdbcEnvironmentInitiator.java:35)at org.hibernate.boot.registry.internal.StandardServiceRegistryImpl.initiateService(StandardServiceRegistryImpl.java:88)at org.hibernate.service.internal.AbstractServiceRegistryImpl.createService(AbstractServiceRegistryImpl.java:259)... 34 moreCaused by: com.mysql.jdbc.exceptions.jdbc4.CommunicationsException: Communications link failureThe last packet sent successfully to the server was 0 milliseconds ago. The driver has not received any packets from the server.at sun.reflect.NativeConstructorAccessorImpl.newInstance0(Native Method)at sun.reflect.NativeConstructorAccessorImpl.newInstance(NativeConstructorAccessorImpl.java:62)at sun.reflect.DelegatingConstructorAccessorImpl.newInstance(DelegatingConstructorAccessorImpl.java:45)at java.lang.reflect.Constructor.newInstance(Constructor.java:423)at com.mysql.jdbc.Util.handleNewInstance(Util.java:425)at com.mysql.jdbc.SQLError.createCommunicationsException(SQLError.java:990)at com.mysql.jdbc.MysqlIO.<init>(MysqlIO.java:341)at com.mysql.jdbc.ConnectionImpl.coreConnect(ConnectionImpl.java:2186)at com.mysql.jdbc.ConnectionImpl.connectOneTryOnly(ConnectionImpl.java:2219)at com.mysql.jdbc.ConnectionImpl.createNewIO(ConnectionImpl.java:2014)at com.mysql.jdbc.ConnectionImpl.<init>(ConnectionImpl.java:776)at com.mysql.jdbc.JDBC4Connection.<init>(JDBC4Connection.java:47)at sun.reflect.NativeConstructorAccessorImpl.newInstance0(Native Method)at sun.reflect.NativeConstructorAccessorImpl.newInstance(NativeConstructorAccessorImpl.java:62)at sun.reflect.DelegatingConstructorAccessorImpl.newInstance(DelegatingConstructorAccessorImpl.java:45)at java.lang.reflect.Constructor.newInstance(Constructor.java:423)at com.mysql.jdbc.Util.handleNewInstance(Util.java:425)at com.mysql.jdbc.ConnectionImpl.getInstance(ConnectionImpl.java:386)at com.mysql.jdbc.NonRegisteringDriver.connect(NonRegisteringDriver.java:330)at org.hibernate.engine.jdbc.connections.internal.DriverConnectionCreator.makeConnection(DriverConnectionCreator.java:38)... 49 moreCaused by: java.net.ConnectException: Connection refused (Connection refused)at java.net.PlainSocketImpl.socketConnect(Native Method)at java.net.AbstractPlainSocketImpl.doConnect(AbstractPlainSocketImpl.java:350)at java.net.AbstractPlainSocketImpl.connectToAddress(AbstractPlainSocketImpl.java:206)at java.net.AbstractPlainSocketImpl.connect(AbstractPlainSocketImpl.java:188)at java.net.SocksSocketImpl.connect(SocksSocketImpl.java:392)at java.net.Socket.connect(Socket.java:589)at com.mysql.jdbc.StandardSocketFactory.connect(StandardSocketFactory.java:211)at com.mysql.jdbc.MysqlIO.<init>(MysqlIO.java:300)... 62 more]]>
    </error>
  </testcase> <!-- setUp -->
</testsuite> <!-- com.java4qa.addressbook.tests.ContactAddToGroupTests -->
